Workbook

Sheet Sample information
A1: Mseq300
A2: Unique number for M300 | B2: Tube # by user | C2: Our Tube # | D2: Site information | F2: QC qPCR | G2: To be sequenced by NovaSeq | H2: Brain | I2: Region | J2: Expected | K2: Original mseq # | L2: RT primers for MAPseq | M2: i7 (top strand) 10nt | N2: i5 (top strand) 10nt
A3: 1 | B3: 19 | C3: V1 injection site | D3: injection | E3: √ | F3: √ | G3: yes | H3: M761 | K3: M256 | L3: 97 | M3: ACCGCGGGAT | N3: ACGGCTTCAA
A4: 2 | B4: 20 | C4: RSP | D4: target | E4: √ | G4: yes | H4: M761 | K4: M256 | L4: 1 | M4: ATCACTGGAT | N4: ACATGCGCTC
A5: 3 | B5: 21 | C5: RM | D5: target | E5: √ | F5: √ | G5: yes | H5: M761 | K5: M256 | L5: 2 | M5: GGATTATCAT | N5: ACGCTACCGA
A6: 4 | B6: 22 | C6: AM | D6: target | E6: √ | G6: yes | H6: M761 | K6: M256 | L6: 3 | M6: ATATTAAGAT | N6: ACGATTCCCA
A7: 5 | B7: 23 | C7: A | D7: target | E7: √ | G7: yes | H7: M761 | K7: M256 | L7: 4 | M7: TATGTATTAT | N7: ACAGAAACCA
A8: 6 | B8: 24 | C8: RL | D8: target | E8: √ | F8: √ | G8: yes | H8: M761 | K8: M256 | L8: 5 | M8: CGCCATTTAT | N8: ACGTACATTA
A9: 7 | B9: 25 | C9: AL | D9: target | E9: √ | F9: √√ | G9: yes | H9: M761 | K9: M256 | L9: 6 | M9: ATAAAAACAT | N9: ACCCCATAGT | P9: Plate 1 | Q9: 1 | R9: 2 | S9: 3 | T9: 4 | U9: 5 | V9: 6 | W9: 7 | X9: 8 | Y9: 9 | Z9: 10 | AA9: 11 | AB9: 12
A10: 8 | B10: 26 | C10: LM/Li | D10: target | E10: √ | F10: √ | G10: yes | H10: M761 | K10: M256 | L10: 7 | M10: CTAAAACTAT | N10: ACCATGGTAC | P10: A | Q10: 1 | R10: 9 | S10: 17 | T10: 25 | U10: 33 | V10: 41 | W10: 49 | X10: 57 | Y10: 65 | Z10: 73 | AA10: 81 | AB10: 89
A11: 9 | B11: 27 | C11: Cerebellum - Control | D11: target-negative | E11: √ | F11: √ | G11: yes | H11: M761 | K11: M256 | L11: 8 | M11: CGCGCGATAT | N11: ACTAAGCCCC | P11: B | Q11: 2 | R11: 10 | S11: 18 | T11: 26 | U11: 34 | V11: 42 | W11: 50 | X11: 58 | Y11: 66 | Z11: 74 | AA11: 82 | AB11: 90
A12: 10 | B12: 10 | C12: V1 - injection site | D12: injection | E12: √√ | F12: √√ | G12: yes | H12: M760 | K12: M256 | L12: 98 | M12: AAAGTGAAAT | N12: ACAAGTCAAT | P12: C | Q12: 3 | R12: 11 | S12: 19 | T12: 27 | U12: 35 | V12: 43 | W12: 51 | X12: 59 | Y12: 67 | Z12: 75 | AA12: 83 | AB12: 91
A13: 11 | B13: 11 | C13: RSP | D13: target | G13: yes | H13: M760 | K13: M256 | L13: 9 | M13: TTTGCGAGAT | N13: ACCCGGCGCG | P13: D | Q13: 4 | R13: 12 | S13: 20 | T13: 28 | U13: 36 | V13: 44 | W13: 52 | X13: 60 | Y13: 68 | Z13: 76 | AA13: 84 | AB13: 92
A14: 12 | B14: 12 | C14: PM | D14: target | E14: √√ | F14: √√ | G14: yes | H14: M760 | K14: M256 | L14: 10 | M14: ACAGCCTCAT | N14: ACAGATGACA | P14: E | Q14: 5 | R14: 13 | S14: 21 | T14: 29 | U14: 37 | V14: 45 | W14: 53 | X14: 61 | Y14: 69 | Z14: 77 | AA14: 85 | AB14: 93
A15: 13 | B15: 13 | C15: AM | D15: target | G15: yes | H15: M760 | K15: M256 | L15: 11 | M15: AGGCGAGGAT | N15: ACGTTGCGGG | P15: F | Q15: 6 | R15: 14 | S15: 22 | T15: 30 | U15: 38 | V15: 46 | W15: 54 | X15: 62 | Y15: 70 | Z15: 78 | AA15: 86 | AB15: 94
A16: 14 | B16: 15 | C16: RL | D16: target | G16: yes | H16: M760 | K16: M256 | L16: 12 | M16: TTACGTTTAT | N16: ACTACGAGAT | P16: G | Q16: 7 | R16: 15 | S16: 23 | T16: 31 | U16: 39 | V16: 47 | W16: 55 | X16: 63 | Y16: 71 | Z16: 79 | AA16: 87 | AB16: 95
A17: 15 | B17: 16 | C17: AL | D17: target | E17: √√ | F17: √√ | G17: yes | H17: M760 | K17: M256 | L17: 13 | M17: CCCGTCTTAT | N17: ACTTACACAT | P17: H | Q17: 8 | R17: 16 | S17: 24 | T17: 32 | U17: 40 | V17: 48 | W17: 56 | X17: 64 | Y17: 72 | Z17: 80 | AA17: 88 | AB17: 96
A18: 16 | B18: 17 | C18: LM/Li | D18: target | G18: yes | H18: M760 | K18: M256 | L18: 14 | M18: GTCCGAGCAT | N18: ACGTGCTCCA
A19: 17 | B19: 18 | C19: Cerebellum - negative control | D19: target-negative | E19: √√ | F19: √√ | G19: yes | H19: M760 | K19: M256 | L19: 15 | M19: AGTATATAAT | N19: ACGTAGAGGC
A20: 18 | B20: 1 | C20: V1 - injection site | D20: injection | E20: √√ | F20: √√ | G20: yes | H20: M759 | K20: M256 | L20: 99 | M20: AGAGACGGAT | N20: ACGCAAATAA | P20: Plate 2 | Q20: 1 | R20: 2 | S20: 3 | T20: 4 | U20: 5 | V20: 6 | W20: 7 | X20: 8 | Y20: 9 | Z20: 10 | AA20: 11 | AB20: 12
A21: 19 | B21: 2 | C21: RSP | D21: target | G21: yes | H21: M759 | K21: M256 | L21: 16 | M21: CTGGTGTTAT | N21: ACTAGGTCAC | P21: A | Q21: 97 | R21: 105 | S21: 113 | T21: 121 | U21: 129 | V21: 137 | W21: 145 | X21: 153 | Y21: 161 | Z21: 169 | AA21: 177 | AB21: 185
A22: 20 | B22: 3 | C22: PM | D22: target | E22: √√ | F22: √√ | G22: yes | H22: M759 | K22: M256 | L22: 17 | M22: CGGGGCCCAT | N22: ACTAGTTGGC | P22: B | Q22: 98 | R22: 106 | S22: 114 | T22: 122 | U22: 130 | V22: 138 | W22: 146 | X22: 154 | Y22: 162 | Z22: 170 | AA22: 178 | AB22: 186
A23: 21 | B23: 4 | C23: AM | D23: target | G23: yes | H23: M759 | K23: M256 | L23: 18 | M23: GCTCTGTCAT | N23: ACCGATTGCT | P23: C | Q23: 99 | R23: 107 | S23: 115 | T23: 123 | U23: 131 | V23: 139 | W23: 147 | X23: 155 | Y23: 163 | Z23: 171 | AA23: 179 | AB23: 187
A24: 22 | B24: 7 | C24: AL | D24: target | E24: √√ | F24: √√ | G24: yes | H24: M759 | K24: M256 | L24: 19 | M24: TCGTCGCTAT | N24: ACCAAACGTC | P24: D | Q24: 100 | R24: 108 | S24: 116 | T24: 124 | U24: 132 | V24: 140 | W24: 148 | X24: 156 | Y24: 164 | Z24: 172 | AA24: 180 | AB24: 188
A25: 23 | B25: 8 | C25: LM/Li | D25: target | G25: yes | H25: M759 | K25: M256 | L25: 20 | M25: ATTGGGACAT | N25: ACCCCTCCGT | P25: E | Q25: 101 | R25: 109 | S25: 117 | T25: 125 | U25: 133 | V25: 141 | W25: 149 | X25: 157 | Y25: 165 | Z25: 173 | AA25: 181 | AB25: 189
A26: 24 | B26: 9 | C26: Cerebellum - negative control | D26: target-negative | E26: √√ | F26: √√ | G26: yes | H26: M759 | K26: M256 | L26: 21 | M26: CATCAATCAT | N26: ACCACAAGGT | P26: F | Q26: 102 | R26: 110 | S26: 118 | T26: 126 | U26: 134 | V26: 142 | W26: 150 | X26: 158 | Y26: 166 | Z26: 174 | AA26: 182 | AB26: 190
A27: 25 | B27: 10 | C27: V1 - injection site | D27: injection | E27: √ | F27: √ | G27: yes | H27: JR0548 | K27: M292 | L27: 100 | M27: ATAACGTGAT | N27: ACTTCTGTGT | P27: G | Q27: 103 | R27: 111 | S27: 119 | T27: 127 | U27: 135 | V27: 143 | W27: 151 | X27: 159 | Y27: 167 | Z27: 175 | AA27: 183 | AB27: 191
A28: 26 | B28: 11 | C28: RSP | D28: target | G28: yes | H28: JR0548 | K28: M292 | L28: 22 | M28: AACAGGTCAT | N28: ACTTTAGATT | P28: H | Q28: 104 | R28: 112 | S28: 120 | T28: 128 | U28: 136 | V28: 144 | W28: 152 | X28: 160 | Y28: 168 | Z28: 176 | AA28: 184 | AB28: 192
A29: 27 | B29: 12 | C29: PM | D29: target | G29: yes | H29: JR0548 | K29: M292 | L29: 23 | M29: TTGGGTGCAT | N29: ACAGACCACG
A30: 28 | B30: 13 | C30: AM | D30: target | G30: yes | H30: JR0548 | K30: M292 | L30: 24 | M30: ATCGTTTCAT | N30: ACGAGTGGGG
A31: 29 | B31: 15 | C31: RL | D31: target | G31: yes | H31: JR0548 | K31: M292 | L31: 25 | M31: GAAAGGGAAT | N31: ACATTGATAT | P31: Plate 3 | Q31: 1 | R31: 2 | S31: 3 | T31: 4 | U31: 5 | V31: 6 | W31: 7 | X31: 8 | Y31: 9 | Z31: 10 | AA31: 11 | AB31: 12
A32: 30 | B32: 16 | C32: AL | D32: target | G32: yes | H32: JR0548 | K32: M292 | L32: 26 | M32: GGCAAGATAT | N32: ACCTGTATTA | P32: A | Q32: 193 | R32: 201 | S32: 209 | T32: 217 | U32: 225 | V32: 233 | W32: 241 | X32: 249 | Y32: 257 | Z32: 265 | AA32: 273 | AB32: 281
A33: 31 | B33: 17 | C33: LM/Li | D33: target | E33: √ | F33: √ | G33: yes | H33: JR0548 | K33: M292 | L33: 27 | M33: GGTCCGATAT | N33: ACCTGGAGCC | P33: B | Q33: 194 | R33: 202 | S33: 210 | T33: 218 | U33: 226 | V33: 234 | W33: 242 | X33: 250 | Y33: 258 | Z33: 266 | AA33: 274 | AB33: 282
A34: 32 | B34: 18 | C34: Cerebellum - negative control | D34: target-negative | E34: √ | F34: √ | G34: yes | H34: JR0548 | K34: M292 | L34: 28 | M34: ACATGCCTAT | N34: ACATTCCGCA | P34: C | Q34: 195 | R34: 203 | S34: 211 | T34: 219 | U34: 227 | V34: 235 | W34: 243 | X34: 251 | Y34: 259 | Z34: 267 | AA34: 275 | AB34: 283
A35: 33 | B35: 19 | C35: V1 - injection site | D35: injection | E35: √ | F35: √ | G35: yes | H35: JR0552 | K35: M292 | L35: 101 | M35: TTAATGTTAT | N35: ACTACTGGCA | P35: D | Q35: 196 | R35: 204 | S35: 212 | T35: 220 | U35: 228 | V35: 236 | W35: 244 | X35: 252 | Y35: 260 | Z35: 268 | AA35: 276 | AB35: 284
A36: 34 | B36: 20 | C36: RSP | D36: target | G36: yes | H36: JR0552 | K36: M292 | L36: 29 | M36: TTTCGCTGAT | N36: ACAATATATT | P36: E | Q36: 197 | R36: 205 | S36: 213 | T36: 221 | U36: 229 | V36: 237 | W36: 245 | X36: 253 | Y36: 261 | Z36: 269 | AA36: 277 | AB36: 285
A37: 35 | B37: 21 | C37: PM | D37: target | G37: yes | H37: JR0552 | K37: M292 | L37: 30 | M37: ACGGTACTAT | N37: ACAGCAAAGG | P37: F | Q37: 198 | R37: 206 | S37: 214 | T37: 222 | U37: 230 | V37: 238 | W37: 246 | X37: 254 | Y37: 262 | Z37: 270 | AA37: 278 | AB37: 286
A38: 36 | B38: 22 | C38: AM | D38: target | G38: yes | H38: JR0552 | K38: M292 | L38: 31 | M38: GGTAAGTAAT | N38: ACTGTTAGGA | P38: G | Q38: 199 | R38: 207 | S38: 215 | T38: 223 | U38: 231 | V38: 239 | W38: 247 | X38: 255 | Y38: 263 | Z38: 271 | AA38: 279 | AB38: 287
A39: 37 | B39: 24 | C39: RL | D39: target | G39: yes | H39: JR0552 | K39: M292 | L39: 32 | M39: CGCGAGGAAT | N39: ACGGGACCCC | P39: H | Q39: 200 | R39: 208 | S39: 216 | T39: 224 | U39: 232 | V39: 240 | W39: 248 | X39: 256 | Y39: 264 | Z39: 272 | AA39: 280 | AB39: 288
A40: 38 | B40: 25 | C40: AL | D40: target | G40: yes | H40: JR0552 | K40: M292 | L40: 33 | M40: CTCGCTTTAT | N40: ACTGACTAGT
...

Sheet PCR2 primers
A1: Old plate nomenclature | B1: MAP2 Plate | C1: Well Position | E1: i7 (top strand) 10nt | F1: i5 (top strand) 10nt
A2: 1 | B2: 1 | C2: a | D2: 1 | E2: ATCACTGGAT | F2: ACATGCGCTC
A3: 2 | B3: 1 | C3: b | D3: 1 | E3: GGATTATCAT | F3: ACGCTACCGA
A4: 3 | B4: 1 | C4: c | D4: 1 | E4: ATATTAAGAT | F4: ACGATTCCCA
A5: 4 | B5: 1 | C5: d | D5: 1 | E5: TATGTATTAT | F5: ACAGAAACCA
A6: 5 | B6: 1 | C6: e | D6: 1 | E6: CGCCATTTAT | F6: ACGTACATTA
A7: 6 | B7: 1 | C7: f | D7: 1 | E7: ATAAAAACAT | F7: ACCCCATAGT
A8: 7 | B8: 1 | C8: g | D8: 1 | E8: CTAAAACTAT | F8: ACCATGGTAC
A9: 8 | B9: 1 | C9: h | D9: 1 | E9: CGCGCGATAT | F9: ACTAAGCCCC
A10: 9 | B10: 1 | C10: a | D10: 2 | E10: TTTGCGAGAT | F10: ACCCGGCGCG
A11: 10 | B11: 1 | C11: b | D11: 2 | E11: ACAGCCTCAT | F11: ACAGATGACA
A12: 11 | B12: 1 | C12: c | D12: 2 | E12: AGGCGAGGAT | F12: ACGTTGCGGG
A13: 12 | B13: 1 | C13: d | D13: 2 | E13: TTACGTTTAT | F13: ACTACGAGAT
... A289: 288 | B289: 3 | C289: h | D289: 12 | E289: ACGGATTAAT | F289: ACCACATCCA

Sheet Input
A1: CT result input
A2: Well | B2: Well Position | C2: Imput CT | J2: Note:
A3: 1 | B3: A1
A4: 2 | B4: A2
A5: 3 | B5: A3
A6: 4 | B6: A4
A7: 5 | B7: A5
A8: 6 | B8: A6 | K8: gfp | L8: actin | M8: gfp | N8: acitin
A9: 7 | B9: A7 | K9: 1~3 | L9: 4~6 | M9: 7~9 | N9: 10~12
A10: 8 | B10: A8 | K10: sample1 | M10: sample 9
A11: 9 | B11: A9 | K11: sample2 | M11: sample 10
A12: 10 | B12: A10 | K12: sample3 | M12: sample 11
A13: 11 | B13: A11 | K13: sample4 | M13: sample 12
A14: 12 | B14: A12 | K14: sample5 | M14: sample 13
A15: 13 | B15: B1 | K15: sample6 | M15: sample 14
A16: 14 | B16: B2 | K16: sample7 | M16: sample 15
A17: 15 | B17: B3 | K17: sample8 | M17: sample 16
A18: 16 | B18: B4
A19: 17 | B19: B5
A20: 18 | B20: B6
A21: 19 | B21: B7
A22: 20 | B22: B8
A23: 21 | B23: B9
A24: 22 | B24: B10
A25: 23 | B25: B11
A26: 24 | B26: B12
A27: 25 | B27: C1
A28: 26 | B28: C2
A29: 27 | B29: C3
... A98: 96 | B98: H12

Sheet QC result
B1: CT gfp | C1: CT actin | D1: mean gfp | E1: mean actin | F1: ∆CT
A2: 1 | B2: =Input!C3 -> 0 | C2: =Input!C6 -> 0 | D2: =AVERAGE(B2:B4) -> 0 | E2: =AVERAGE(C2:C4) -> 0 | F2: =D2-E2 -> 0
B3: =Input!C4 -> 0 | C3: =Input!C7 -> 0
B4: =Input!C5 -> 0 | C4: =Input!C8 -> 0
A5: 2 | B5: =Input!C15 -> 0 | C5: =Input!C18 -> 0 | D5: =AVERAGE(B5:B7) -> 0 | E5: =AVERAGE(C5:C7) -> 0 | F5: =D5-E5 -> 0
B6: =Input!C16 -> 0 | C6: =Input!C19 -> 0
B7: =Input!C17 -> 0 | C7: =Input!C20 -> 0
A8: 3 | B8: =Input!C27 -> 0 | C8: =Input!C30 -> 0 | D8: =AVERAGE(B8:B10) -> 0 | E8: =AVERAGE(C8:C10) -> 0 | F8: =D8-E8 -> 0
B9: =Input!C28 -> 0 | C9: =Input!C31 -> 0
B10: =Input!C29 -> 0 | C10: =Input!C32 -> 0
A11: 4 | B11: =Input!C39 -> 0 | C11: =Input!C42 -> 0 | D11: =AVERAGE(B11:B13) -> 0 | E11: =AVERAGE(C11:C13) -> 0 | F11: =D11-E11 -> 0
B12: =Input!C40 -> 0 | C12: =Input!C43 -> 0
B13: =Input!C41 -> 0 | C13: =Input!C44 -> 0
A14: 5 | B14: =Input!C51 -> 0 | C14: =Input!C54 -> 0 | D14: =AVERAGE(B14:B16) -> 0 | E14: =AVERAGE(C14:C16) -> 0 | F14: =D14-E14 -> 0
B15: =Input!C52 -> 0 | C15: =Input!C55 -> 0
B16: =Input!C53 -> 0 | C16: =Input!C56 -> 0
A17: 6 | B17: =Input!C63 -> 0 | C17: =Input!C66 -> 0 | D17: =AVERAGE(B17:B19) -> 0 | E17: =AVERAGE(C17:C19) -> 0 | F17: =D17-E17 -> 0
B18: =Input!C64 -> 0 | C18: =Input!C67 -> 0
B19: =Input!C65 -> 0 | C19: =Input!C68 -> 0
A20: 7 | B20: =Input!C75 -> 0 | C20: =Input!C78 -> 0 | D20: =AVERAGE(B20:B22) -> 0 | E20: =AVERAGE(C20:C22) -> 0 | F20: =D20-E20 -> 0
B21: =Input!C76 -> 0 | C21: =Input!C79 -> 0
B22: =Input!C77 -> 0 | C22: =Input!C80 -> 0
A23: 8 | B23: =Input!C87 -> 0 | C23: =Input!C90 -> 0 | D23: =AVERAGE(B23:B25) -> 0 | E23: =AVERAGE(C23:C25) -> 0 | F23: =D23-E23 -> 0
B24: =Input!C88 -> 0 | C24: =Input!C91 -> 0
B25: =Input!C89 -> 0 | C25: =Input!C92 -> 0
A26: 9 | B26: =Input!C9 -> 0 | C26: =Input!C12 -> 0 | D26: =AVERAGE(B26:B28) -> 0 | E26: =AVERAGE(C26:C28) -> 0 | F26: =D26-E26 -> 0
B27: =Input!C10 -> 0 | C27: =Input!C13 -> 0
B28: =Input!C11 -> 0 | C28: =Input!C14 -> 0
A29: 10 | B29: =Input!C21 -> 0 | C29: =Input!C24 -> 0 | D29: =AVERAGE(B29:B31) -> 0 | E29: =AVERAGE(C29:C31) -> 0 | F29: =D29-E29 -> 0
B30: =Input!C22 -> 0 | C30: =Input!C25 -> 0
B31: =Input!C23 -> 0 | C31: =Input!C26 -> 0
A32: 11 | B32: =Input!C33 -> 0 | C32: =Input!C36 -> 0 | D32: =AVERAGE(B32:B34) -> 0 | E32: =AVERAGE(C32:C34) -> 0 | F32: =D32-E32 -> 0
B33: =Input!C34 -> 0 | C33: =Input!C37 -> 0
B34: =Input!C35 -> 0 | C34: =Input!C38 -> 0
A35: 12 | B35: =Input!C45 -> 0 | C35: =Input!C48 -> 0 | D35: =AVERAGE(B35:B37) -> 0 | E35: =AVERAGE(C35:C37) -> 0 | F35: =D35-E35 -> 0
B36: =Input!C46 -> 0 | C36: =Input!C49 -> 0
B37: =Input!C47 -> 0 | C37: =Input!C50 -> 0
A38: 13 | B38: =Input!C57 -> 0 | C38: =Input!C60 -> 0 | D38: =AVERAGE(B38:B40) -> 0 | E38: =AVERAGE(C38:C40) -> 0 | F38: =D38-E38 -> 0
B39: =Input!C58 -> 0 | C39: =Input!C61 -> 0
B40: =Input!C59 -> 0 | C40: =Input!C62 -> 0
...

Sheet processing information
B1: general information in RT | C1: DR 05/21/2025
B2: RNA pellets dissolved into H2O (ul) | C2: 13
B3: ul of RNA used for QC dil | C3: 2 ul in 4 ul water
B5: ul of RNA used for real RT | C5: 4
B7: numbers of injection sites processed | C7: 14
B8: numbers of target sites pooled before 2nd strand cDNA synthesis | C8: 83
B9: number of reaction for 2nd cDNA synthesis | C9: NA
B11: For injection site | C11: DR 05/21/2025 | G11: For target site | H11: DR 05/21/2025
B12: PCR I reation volume per site (ul) | C12: 25 | G12: PCR I reation volume pooled (ul) | H12: =250*C9 -> #VALUE!
B13: PCR I cycle number | C13: 15x | G13: PCR I cycle number | H13: 15x
B14: PCR I extention time | C14: 30 sec | G14: PCR I extention time | H14: 30 sec
B16: PCR II reation volume per site (ul) | C16: 25 | G16: PCR II test volume ul | H16: 25
B17: PCR II test cycles | C17: 11, 14, 17, 20, 23, 26 | G17: PCR II test cycles | H17: 14, 17, 20, 23, 26, 29
B18: Gel purification from cycles# | C18: 13 | G18: Optimal cycles# | H18: 24
B19: PCR II extention time | C19: 30 sec
G20: PCRII extention time | H20: 2 min
G21: PCR II volume for real run ul | H21: 25ul
G22: PCR II cycle number for real run | H22: 24
G23: Wells used on the gel | H23: 2
H26: PCR II cycle calculator | J26: need input
H28: Test Template (ul) | I28: Test Volume (ul) | K28: Real Run Template Volume (ul) | L28: Real Volume (ul)
H29: 0.1 | I29: 25 | K29: 62 | L29: 1000
H31: concT | I31: =H29/I29 -> 0.004 | K31: concR | L31: =K29/L29 -> 0.062
G34: concR/ConcT | H34: Difference1 | I34: =(L31/I31)/H23 -> 7.75
G36: VR/VT | H36: Difference2 | I36: =(L29/2)/I29 -> 20
H38: Difference Total | I38: =I34*I36 -> 155
H39: Cycle difference | I39: =LOG(I38,2) -> 7.2761244
H41: Test cycle number | I41: 23
H43: cycle number for real run | I43: =I41-I39 -> 15.723876

Sheet Bioanalyzer&Q-PCR
C2: For injection site I | E2: DR 05/21/2025 | H2: For injection site II | J2: example
D3: ul of H2O used to elute the gel product | E3: 13 ul | I3: ul of H2O used to elute the gel product | J3: 13 ul
D4: Concentration of purified gel product based on nanadrop (ng/ul) | E4: 250ng/ul | I4: Concentration of purified gel product based on nanadrop (ng/ul) | J4: 30ng/ul
D5: Dilution used for bioanalyzer | E5: 125 | I5: Dilution used for bioanalyzer | J5: 20
D6: Concentration of purified gel product based on Bioanalyzer (nM) | E6: 3.5 | I6: Concentration of purified gel product based on Bioanalyzer (nM) | J6: 5
C7: Formula used | D7: Original concentration before dilution (nM) | E7: =E5*E6 -> 437.5 | H7: Formula used | I7: Original concentration before dilution (nM) | J7: =J6*J5 -> 100
D8: Size of purified gel product based on Bioanalyzer | E8: 226 bp | I8: Size of purified gel product based on Bioanalyzer | J8: 233 bp
C11: Formula used | D11: dilution required to get 4nM | E11: =E7/4 -> 109.375 | H11: Formula used | I11: dilution required to get 5nM | J11: =J7/5 -> 20
D12: ul used for dilution to get 4nM | E12: 2 | I12: ul used for dilution to get 5nM | J12: 2
C13: Formula used | D13: H2O need to add for this dilution | E13: =E12*E11-E12 -> 216.75 | H13: Formula used | I13: H2O need to add for this dilution | J13: =J12*J11-J12 -> 38
C14: Formula used | D14: Final volume after dilution | E14: =E12*E11 -> 218.75 | H14: Formula used | I14: Final volume after dilution | J14: =J12*J11 -> 40
D16: Volume used for sending NGS library | E16: =F36 -> 15 | I16: Volume used for sending NGS library | J16: =F37 -> 0
C19: For pooled target site | E19: DR 05/21/2025
D20: ul of H2O used to elute the gel product | E20: 13 ul
D21: Concentration of purified gel product based on nanadrop (ng/ul) | E21: 400ng/ul | H21: Library sumission calculations
D22: Dilution used for bioanalyzer | E22: 200 | H22: 14inj sites x 50m = 700M | J22: 0.25
D23: Concentration of purified gel product based on Bioanalyzer (nM) | E23: 2.5 | H23: 83target sites x 25M = 2075M | J23: 0.75
C24: Formula used | D24: Original concentration before dilution (nM) | E24: =E23*E22 -> 500
D25: Size of purified gel product based on Bioanalyzer | E25: 227 bp
C28: Formula used | D28: dilution required to get 4nM | E28: =E24/4 -> 125
D29: ul used for dilution to get 4nM | E29: 2
C30: Formula used | D30: H2O need to add for this dilution | E30: =E29*E28-E29 -> 248
C31: Formula used | D31: Final volume after dilution | E31: =E29*E28 -> 250
D33: Volume used for sending NGS library | E33: =F38 -> 45
E35: % | F35: ul
D36: % of Injection site I for NGS | E36: 25 | F36: =0.01*E36*E40 -> 15 | G36: Formula used
D37: % of Injection site II for NGS | E37: 0 | F37: =0.01*E37*E40 -> 0 | G37: Formula used
D38: % of Pooled target site for NGS | E38: 75 | F38: =0.01*E38*E40 -> 45 | G38: Formula used
D40: Final volume submitted for NGS ul | E40: 60

Sheet Summary_libquantification
B3: Key In sample number | J3: samplenumer
C4: Raw Loading pM | E4: actual concentration of library | F4: target concentration | G4: actual conc | H4: volume | I4: volume to add in ul | J4: 6 | K4: mouse | L4: scalefactor | M4: 1 | O4: percentage of reads
B5: 1 | C5: 34 | E5: =10/C5*10 -> 2.9411765 | F5: 20 | G5: =F5/$J$4 -> 3.3333333 | H5: =G5/E5 -> 1.1333333 | I5: =$M$4*H5 -> 1.1333333 | O5: =F5/SUM(F$5:F$10)*100 -> 16.666667
B6: 2 | C6: 100 | E6: =10/C6*10 -> 1 | F6: 20 | G6: =F6/$J$4 -> 3.3333333 | H6: =G6/E6 -> 3.3333333 | I6: =$M$4*H6 -> 3.3333333 | O6: =F6/SUM(F$5:F10)*100 -> 16.666667
B7: 3 | C7: 71.534769 | E7: =10/C7*10 -> 1.3979216 | F7: 20 | G7: =F7/$J$4 -> 3.3333333 | H7: =G7/E7 -> 2.3844923 | I7: =$M$4*H7 -> 2.3844923 | O7: =F7/SUM(F$5:F$10)*100 -> 16.666667
B8: 4 | C8: 34 | E8: =10/C8*10 -> 2.9411765 | F8: 20 | G8: =F8/$J$4 -> 3.3333333 | H8: =G8/E8 -> 1.1333333 | I8: =$M$4*H8 -> 1.1333333 | O8: =F8/SUM(F$5:F$10)*100 -> 16.666667
B9: 5 | C9: 52.767384 | E9: =10/C9*10 -> 1.89511 | F9: 20 | G9: =F9/$J$4 -> 3.3333333 | H9: =G9/E9 -> 1.7589128 | I9: =$M$4*H9 -> 1.7589128 | O9: =F9/SUM(F$5:F$10)*100 -> 16.666667
B10: 6 | C10: 49.920861 | E10: =10/C10*10 -> 2.0031706 | F10: 20 | G10: =F10/$J$4 -> 3.3333333 | H10: =G10/E10 -> 1.6640287 | I10: =$M$4*H10 -> 1.6640287 | O10: =F10/SUM(F$5:F$10)*100 -> 16.666667
H12: Final volume | I12: =SUM(I5:I10) -> 11.407434
N15: total % | O15: =SUM(O5:O10) -> 100

Sheet NGS submission
B1: Minimum for NGS: 15ul of product @ >3nM
B2: Optimal for NGS: 15 ul of product @~7nM
A3: Sample ID | B3: Sample Name | C3: Working dilution | D3: Run Type | E3: Run Length | F3: #of Lane | G3: Data link
A4: m300 | B4: hzhan_208045 | C4: 4nM | D4: Johns Hopkins NovaSeq
D5: submitted on May 22
